<?xml version="1.0" ?>
<!-- =================================================================================== -->
<!-- |    This document was autogenerated by xacro from /home/student/workspaces/catkin_ws_2/src/multiple_arm_description/urdf/multiple_crisp.urdf.xacro | -->
<!-- |    EDITING THIS FILE BY HAND IS NOT RECOMMENDED                                 | -->
<!-- =================================================================================== -->
<robot name="multiple_crisp">
    // Include urdf.xacro from respective description packages of arms
    <material name="silver">
        <color rgba="0.700 0.700 0.700 1.000" />
    </material>
    <material name="black">
        <color rgba="0.0 0.0 0.0 1.000" />
    </material>
    <!-- <xacro:include filename="$(find robotiq_85_description)/urdf/robotiq_85_gripper.urdf.xacro" /> -->
    // Specify Proper Prefix names for understanding of different arms.
    <!-- params="prefix joint_limited
      shoulder_pan_lower_limit:=${-pi}    shoulder_pan_upper_limit:=${pi}
      shoulder_lift_lower_limit:=${-pi}    shoulder_lift_upper_limit:=${pi}
      elbow_joint_lower_limit:=${-pi}    elbow_joint_upper_limit:=${pi}
      wrist_1_lower_limit:=${-pi}    wrist_1_upper_limit:=${pi}
      wrist_2_lower_limit:=${-pi}    wrist_2_upper_limit:=${pi}
      wrist_3_lower_limit:=${-pi}    wrist_3_upper_limit:=${pi}
      transmission_hw_interface:=hardware_interface/PositionJointInterface
      safety_limits:=false safety_pos_margin:=0.15
      safety_k_position:=20"> -->
    <link name="crisp_1_base_link">
        <inertial>
            <origin rpy="0 0 0" xyz="0.0001603944729273711 -0.0003290623427609323 0.040147411165435416" />
            <mass value="0.6779611564550755" />
            <inertia ixx="0.001015" ixy="1e-06" ixz="0.0" iyy="0.001028" iyz="-2e-06" izz="0.001154" />
        </inertial>
        <visual>
            <origin rpy="0 0 0" xyz="0 0 0" />
            <geometry>
                <mesh filename="package://crisp_description/meshes/base_link.stl" scale="0.001 0.001 0.001" />
            </geometry>
            <material name="silver" />
        </visual>
        <collision>
            <origin rpy="0 0 0" xyz="0 0 0" />
            <geometry>
                <mesh filename="package://crisp_description/meshes/base_link.stl" scale="0.001 0.001 0.001" />
            </geometry>
        </collision>
    </link>
    <link name="crisp_1_shoulder_link">
        <inertial>
            <origin rpy="0 0 0" xyz="4.0011390054304076e-06 -0.00961982769835694 0.045447590610113775" />
            <mass value="0.4336022449379255" />
            <inertia ixx="0.000648" ixy="-0.0" ixz="-1e-06" iyy="0.000565" iyz="4.1e-05" izz="0.000631" />
        </inertial>
        <visual>
            <origin rpy="0 0 0" xyz="-0.000152 4.1e-05 -0.09" />
            <geometry>
                <mesh filename="package://crisp_description/meshes/shoulder_link.stl" scale="0.001 0.001 0.001" />
            </geometry>
            <material name="silver" />
        </visual>
        <collision>
            <origin rpy="0 0 0" xyz="-0.000152 4.1e-05 -0.09" />
            <geometry>
                <mesh filename="package://crisp_description/meshes/shoulder_link.stl" scale="0.001 0.001 0.001" />
            </geometry>
        </collision>
    </link>
    <link name="crisp_1_shoulder_bend">
        <inertial>
            <origin rpy="0 0 0" xyz="-3.977242232601117e-06 -0.045711629373503385 0.012907149486671848" />
            <mass value="0.24798358553552216" />
            <inertia ixx="0.000406" ixy="-1e-06" ixz="-0.0" iyy="0.000397" iyz="2.6e-05" izz="0.00033" />
        </inertial>
        <visual>
            <origin rpy="0 0 0" xyz="-0.000152 0.060041 -0.14" />
            <geometry>
                <mesh filename="package://crisp_description/meshes/shoulder_bend.stl" scale="0.001 0.001 0.001" />
            </geometry>
            <material name="silver" />
        </visual>
        <collision>
            <origin rpy="0 0 0" xyz="-0.000152 0.060041 -0.14" />
            <geometry>
                <mesh filename="package://crisp_description/meshes/shoulder_bend.stl" scale="0.001 0.001 0.001" />
            </geometry>
        </collision>
    </link>
    <link name="crisp_1_tube1">
        <inertial>
            <origin rpy="0 0 0" xyz="-1.218023921678265e-07 4.832804545162883e-07 0.08400037920452025" />
            <mass value="0.1359760217281118" />
            <inertia ixx="0.000423" ixy="-0.0" ixz="0.0" iyy="0.000423" iyz="0.0" izz="0.000207" />
        </inertial>
        <visual>
            <origin rpy="0 0 0" xyz="-0.000152 0.110042 -0.202" />
            <geometry>
                <mesh filename="package://crisp_description/meshes/tube1.stl" scale="0.001 0.001 0.001" />
            </geometry>
            <material name="black" />
        </visual>
        <collision>
            <origin rpy="0 0 0" xyz="-0.000152 0.110042 -0.202" />
            <geometry>
                <mesh filename="package://crisp_description/meshes/tube1.stl" scale="0.001 0.001 0.001" />
            </geometry>
        </collision>
    </link>
    <link name="crisp_1_elbow_link">
        <inertial>
            <origin rpy="0 0 0" xyz="-3.6405482122238116e-06 0.00835316151743537 0.05001631857596067" />
            <mass value="0.5160292603397482" />
            <inertia ixx="0.000905" ixy="1e-06" ixz="1e-06" iyy="0.000814" iyz="-7.4e-05" izz="0.000756" />
        </inertial>
        <visual>
            <origin rpy="0 0 0" xyz="-0.000152 0.110042 -0.37" />
            <geometry>
                <mesh filename="package://crisp_description/meshes/elbow_link.stl" scale="0.001 0.001 0.001" />
            </geometry>
            <material name="silver" />
        </visual>
        <collision>
            <origin rpy="0 0 0" xyz="-0.000152 0.110042 -0.37" />
            <geometry>
                <mesh filename="package://crisp_description/meshes/elbow_link.stl" scale="0.001 0.001 0.001" />
            </geometry>
        </collision>
    </link>
    <link name="crisp_1_elbow_bend">
        <inertial>
            <origin rpy="0 0 0" xyz="-4.075344323087168e-05 0.03327969273841646 -0.01030636733035839" />
            <mass value="0.16999673358161876" />
            <inertia ixx="0.000221" ixy="-0.0" ixz="0.0" iyy="0.000236" iyz="1.7e-05" izz="0.000146" />
        </inertial>
        <visual>
            <origin rpy="0 0 0" xyz="-0.000152 0.050041 -0.431801" />
            <geometry>
                <mesh filename="package://crisp_description/meshes/elbow_bend.stl" scale="0.001 0.001 0.001" />
            </geometry>
            <material name="silver" />
        </visual>
        <collision>
            <origin rpy="0 0 0" xyz="-0.000152 0.050041 -0.431801" />
            <geometry>
                <mesh filename="package://crisp_description/meshes/elbow_bend.stl" scale="0.001 0.001 0.001" />
            </geometry>
        </collision>
    </link>
    <link name="crisp_1_tube2">
        <inertial>
            <origin rpy="0 0 0" xyz="3.31534666480639e-07 -2.8192269833048067e-07 -0.04549993912254768" />
            <mass value="0.035999481079213504" />
            <inertia ixx="3.5e-05" ixy="0.0" ixz="0.0" iyy="3.5e-05" iyz="0.0" izz="2.1e-05" />
        </inertial>
        <visual>
            <origin rpy="0 0 0" xyz="-0.000111 0.010041 -0.37059" />
            <geometry>
                <mesh filename="package://crisp_description/meshes/tube2.stl" scale="0.001 0.001 0.001" />
            </geometry>
            <material name="black" />
        </visual>
        <collision>
            <origin rpy="0 0 0" xyz="-0.000111 0.010041 -0.37059" />
            <geometry>
                <mesh filename="package://crisp_description/meshes/tube2.stl" scale="0.001 0.001 0.001" />
            </geometry>
        </collision>
    </link>
    <link name="crisp_1_wrist_link1">
        <inertial>
            <origin rpy="0 0 0" xyz="3.272677325775889e-07 0.0029345319652001097 -0.03169306675776801" />
            <mass value="0.2120397644725218" />
            <inertia ixx="0.000175" ixy="-0.0" ixz="0.0" iyy="0.00017" iyz="1.1e-05" izz="0.000139" />
        </inertial>
        <visual>
            <origin rpy="0 0 0" xyz="-0.000111 0.010041 -0.27959" />
            <geometry>
                <mesh filename="package://crisp_description/meshes/wrist_link1.stl" scale="0.001 0.001 0.001" />
            </geometry>
            <material name="silver" />
        </visual>
        <collision>
            <origin rpy="0 0 0" xyz="-0.000111 0.010041 -0.27959" />
            <geometry>
                <mesh filename="package://crisp_description/meshes/wrist_link1.stl" scale="0.001 0.001 0.001" />
            </geometry>
        </collision>
    </link>
    <link name="crisp_1_wrist_link2">
        <inertial>
            <origin rpy="0 0 0" xyz="3.2681919059462765e-07 0.034243790458059184 0.003213444605775856" />
            <mass value="0.17601570721446155" />
            <inertia ixx="0.000126" ixy="0.0" ixz="-0.0" iyy="0.000112" iyz="-8e-06" izz="0.000122" />
        </inertial>
        <visual>
            <origin rpy="0 0 0" xyz="-0.000111 -0.024859 -0.23859" />
            <geometry>
                <mesh filename="package://crisp_description/meshes/wrist_link2.stl" scale="0.001 0.001 0.001" />
            </geometry>
            <material name="silver" />
        </visual>
        <collision>
            <origin rpy="0 0 0" xyz="-0.000111 -0.024859 -0.23859" />
            <geometry>
                <mesh filename="package://crisp_description/meshes/wrist_link2.stl" scale="0.001 0.001 0.001" />
            </geometry>
        </collision>
    </link>
    <link name="crisp_1_wrist_link3">
        <inertial>
            <origin rpy="0 0 0" xyz="3.328659660357594e-07 0.003213090953286188 0.03424415588268198" />
            <mass value="0.17601599196961085" />
            <inertia ixx="0.000126" ixy="0.0" ixz="-0.0" iyy="0.000122" iyz="-8e-06" izz="0.000112" />
        </inertial>
        <visual>
            <origin rpy="0 0 0" xyz="-0.000111 -0.064859 -0.27349" />
            <geometry>
                <mesh filename="package://crisp_description/meshes/wrist_link3.stl" scale="0.001 0.001 0.001" />
            </geometry>
            <material name="silver" />
        </visual>
        <collision>
            <origin rpy="0 0 0" xyz="-0.000111 -0.064859 -0.27349" />
            <geometry>
                <mesh filename="package://crisp_description/meshes/wrist_link3.stl" scale="0.001 0.001 0.001" />
            </geometry>
        </collision>
    </link>
    <link name="crisp_1_ee_mount">
        <inertial>
            <origin rpy="0 0 0" xyz="3.3153611991382443e-07 0.0048156835739818354 6.80155745613753e-08" />
            <mass value="0.025997600599102062" />
            <inertia ixx="9e-06" ixy="0.0" ixz="-0.0" iyy="1.7e-05" iyz="0.0" izz="8e-06" />
        </inertial>
        <visual>
            <origin rpy="0 0 0" xyz="-0.000111 -0.099859 -0.31349" />
            <geometry>
                <mesh filename="package://crisp_description/meshes/ee_mount.stl" scale="0.001 0.001 0.001" />
            </geometry>
            <material name="silver" />
        </visual>
        <collision>
            <origin rpy="0 0 0" xyz="-0.000111 -0.099859 -0.31349" />
            <geometry>
                <mesh filename="package://crisp_description/meshes/ee_mount.stl" scale="0.001 0.001 0.001" />
            </geometry>
        </collision>
    </link>
    <joint name="crisp_1_j1" type="revolute">
        <origin rpy="0 0 0" xyz="0.000152 -4.1e-05 0.09" />
        <parent link="crisp_1_base_link" />
        <child link="crisp_1_shoulder_link" />
        <axis xyz="0.0 0.0 1.0" />
        <limit effort="9.2" lower="-6.283185307179586" upper="6.283185307179586" velocity="3.5" />
    </joint>
    <joint name="crisp_1_j2" type="revolute">
        <origin rpy="0 0 0" xyz="0.0 -0.06 0.05" />
        <parent link="crisp_1_shoulder_link" />
        <child link="crisp_1_shoulder_bend" />
        <axis xyz="0.0 -1.0 -0.0" />
        <limit effort="9.2" lower="-6.283185307179586" upper="6.283185307179586" velocity="3.5" />
    </joint>
    <joint name="crisp_1_Rigid 5" type="fixed">
        <origin rpy="0 0 0" xyz="0.0 -0.050001 0.062" />
        <parent link="crisp_1_shoulder_bend" />
        <child link="crisp_1_tube1" />
    </joint>
    <joint name="crisp_1_Rigid 6" type="fixed">
        <origin rpy="0 0 0" xyz="0.0 0.0 0.168" />
        <parent link="crisp_1_tube1" />
        <child link="crisp_1_elbow_link" />
    </joint>
    <joint name="crisp_1_j3" type="revolute">
        <origin rpy="0 0 0" xyz="0.0 0.060001 0.061801" />
        <parent link="crisp_1_elbow_link" />
        <child link="crisp_1_elbow_bend" />
        <axis xyz="-0.0 1.0 0.0" />
        <limit effort="9.2" lower="-6.283185307179586" upper="6.283185307179586" velocity="3.5" />
    </joint>
    <joint name="crisp_1_Rigid 8" type="fixed">
        <origin rpy="0 0 0" xyz="-4.1e-05 0.04 -0.061211" />
        <parent link="crisp_1_elbow_bend" />
        <child link="crisp_1_tube2" />
    </joint>
    <joint name="crisp_1_Rigid 9" type="fixed">
        <origin rpy="0 0 0" xyz="0.0 0.0 -0.091" />
        <parent link="crisp_1_tube2" />
        <child link="crisp_1_wrist_link1" />
    </joint>
    <joint name="crisp_1_j4" type="revolute">
        <origin rpy="0 0 0" xyz="0.0 0.0349 -0.041" />
        <parent link="crisp_1_wrist_link1" />
        <child link="crisp_1_wrist_link2" />
        <axis xyz="-0.0 1.0 0.0" />
        <limit effort="3.3" lower="-6.283185307179586" upper="6.283185307179586" velocity="3.2" />
    </joint>
    <joint name="crisp_1_j5" type="revolute">
        <origin rpy="0 0 0" xyz="0.0 0.04 0.0349" />
        <parent link="crisp_1_wrist_link2" />
        <child link="crisp_1_wrist_link3" />
        <axis xyz="-0.0 0.0 1.0" />
        <limit effort="3.3" lower="-6.283185307179586" upper="6.283185307179586" velocity="3.2" />
    </joint>
    <joint name="crisp_1_j6" type="revolute">
        <origin rpy="0 0 0" xyz="0.0 0.035 0.04" />
        <parent link="crisp_1_wrist_link3" />
        <child link="crisp_1_ee_mount" />
        <axis xyz="-0.0 -1.0 -0.0" />
        <limit effort="3.3" lower="-6.283185307179586" upper="6.283185307179586" velocity="3.2" />
    </joint>
    <!-- params="prefix joint_limited
      shoulder_pan_lower_limit:=${-pi}    shoulder_pan_upper_limit:=${pi}
      shoulder_lift_lower_limit:=${-pi}    shoulder_lift_upper_limit:=${pi}
      elbow_joint_lower_limit:=${-pi}    elbow_joint_upper_limit:=${pi}
      wrist_1_lower_limit:=${-pi}    wrist_1_upper_limit:=${pi}
      wrist_2_lower_limit:=${-pi}    wrist_2_upper_limit:=${pi}
      wrist_3_lower_limit:=${-pi}    wrist_3_upper_limit:=${pi}
      transmission_hw_interface:=hardware_interface/PositionJointInterface
      safety_limits:=false safety_pos_margin:=0.15
      safety_k_position:=20"> -->
    <link name="crisp_2_base_link">
        <inertial>
            <origin rpy="0 0 0" xyz="0.0001603944729273711 -0.0003290623427609323 0.040147411165435416" />
            <mass value="0.6779611564550755" />
            <inertia ixx="0.001015" ixy="1e-06" ixz="0.0" iyy="0.001028" iyz="-2e-06" izz="0.001154" />
        </inertial>
        <visual>
            <origin rpy="0 0 0" xyz="0 0 0" />
            <geometry>
                <mesh filename="package://crisp_description/meshes/base_link.stl" scale="0.001 0.001 0.001" />
            </geometry>
            <material name="silver" />
        </visual>
        <collision>
            <origin rpy="0 0 0" xyz="0 0 0" />
            <geometry>
                <mesh filename="package://crisp_description/meshes/base_link.stl" scale="0.001 0.001 0.001" />
            </geometry>
        </collision>
    </link>
    <link name="crisp_2_shoulder_link">
        <inertial>
            <origin rpy="0 0 0" xyz="4.0011390054304076e-06 -0.00961982769835694 0.045447590610113775" />
            <mass value="0.4336022449379255" />
            <inertia ixx="0.000648" ixy="-0.0" ixz="-1e-06" iyy="0.000565" iyz="4.1e-05" izz="0.000631" />
        </inertial>
        <visual>
            <origin rpy="0 0 0" xyz="-0.000152 4.1e-05 -0.09" />
            <geometry>
                <mesh filename="package://crisp_description/meshes/shoulder_link.stl" scale="0.001 0.001 0.001" />
            </geometry>
            <material name="silver" />
        </visual>
        <collision>
            <origin rpy="0 0 0" xyz="-0.000152 4.1e-05 -0.09" />
            <geometry>
                <mesh filename="package://crisp_description/meshes/shoulder_link.stl" scale="0.001 0.001 0.001" />
            </geometry>
        </collision>
    </link>
    <link name="crisp_2_shoulder_bend">
        <inertial>
            <origin rpy="0 0 0" xyz="-3.977242232601117e-06 -0.045711629373503385 0.012907149486671848" />
            <mass value="0.24798358553552216" />
            <inertia ixx="0.000406" ixy="-1e-06" ixz="-0.0" iyy="0.000397" iyz="2.6e-05" izz="0.00033" />
        </inertial>
        <visual>
            <origin rpy="0 0 0" xyz="-0.000152 0.060041 -0.14" />
            <geometry>
                <mesh filename="package://crisp_description/meshes/shoulder_bend.stl" scale="0.001 0.001 0.001" />
            </geometry>
            <material name="silver" />
        </visual>
        <collision>
            <origin rpy="0 0 0" xyz="-0.000152 0.060041 -0.14" />
            <geometry>
                <mesh filename="package://crisp_description/meshes/shoulder_bend.stl" scale="0.001 0.001 0.001" />
            </geometry>
        </collision>
    </link>
    <link name="crisp_2_tube1">
        <inertial>
            <origin rpy="0 0 0" xyz="-1.218023921678265e-07 4.832804545162883e-07 0.08400037920452025" />
            <mass value="0.1359760217281118" />
            <inertia ixx="0.000423" ixy="-0.0" ixz="0.0" iyy="0.000423" iyz="0.0" izz="0.000207" />
        </inertial>
        <visual>
            <origin rpy="0 0 0" xyz="-0.000152 0.110042 -0.202" />
            <geometry>
                <mesh filename="package://crisp_description/meshes/tube1.stl" scale="0.001 0.001 0.001" />
            </geometry>
            <material name="black" />
        </visual>
        <collision>
            <origin rpy="0 0 0" xyz="-0.000152 0.110042 -0.202" />
            <geometry>
                <mesh filename="package://crisp_description/meshes/tube1.stl" scale="0.001 0.001 0.001" />
            </geometry>
        </collision>
    </link>
    <link name="crisp_2_elbow_link">
        <inertial>
            <origin rpy="0 0 0" xyz="-3.6405482122238116e-06 0.00835316151743537 0.05001631857596067" />
            <mass value="0.5160292603397482" />
            <inertia ixx="0.000905" ixy="1e-06" ixz="1e-06" iyy="0.000814" iyz="-7.4e-05" izz="0.000756" />
        </inertial>
        <visual>
            <origin rpy="0 0 0" xyz="-0.000152 0.110042 -0.37" />
            <geometry>
                <mesh filename="package://crisp_description/meshes/elbow_link.stl" scale="0.001 0.001 0.001" />
            </geometry>
            <material name="silver" />
        </visual>
        <collision>
            <origin rpy="0 0 0" xyz="-0.000152 0.110042 -0.37" />
            <geometry>
                <mesh filename="package://crisp_description/meshes/elbow_link.stl" scale="0.001 0.001 0.001" />
            </geometry>
        </collision>
    </link>
    <link name="crisp_2_elbow_bend">
        <inertial>
            <origin rpy="0 0 0" xyz="-4.075344323087168e-05 0.03327969273841646 -0.01030636733035839" />
            <mass value="0.16999673358161876" />
            <inertia ixx="0.000221" ixy="-0.0" ixz="0.0" iyy="0.000236" iyz="1.7e-05" izz="0.000146" />
        </inertial>
        <visual>
            <origin rpy="0 0 0" xyz="-0.000152 0.050041 -0.431801" />
            <geometry>
                <mesh filename="package://crisp_description/meshes/elbow_bend.stl" scale="0.001 0.001 0.001" />
            </geometry>
            <material name="silver" />
        </visual>
        <collision>
            <origin rpy="0 0 0" xyz="-0.000152 0.050041 -0.431801" />
            <geometry>
                <mesh filename="package://crisp_description/meshes/elbow_bend.stl" scale="0.001 0.001 0.001" />
            </geometry>
        </collision>
    </link>
    <link name="crisp_2_tube2">
        <inertial>
            <origin rpy="0 0 0" xyz="3.31534666480639e-07 -2.8192269833048067e-07 -0.04549993912254768" />
            <mass value="0.035999481079213504" />
            <inertia ixx="3.5e-05" ixy="0.0" ixz="0.0" iyy="3.5e-05" iyz="0.0" izz="2.1e-05" />
        </inertial>
        <visual>
            <origin rpy="0 0 0" xyz="-0.000111 0.010041 -0.37059" />
            <geometry>
                <mesh filename="package://crisp_description/meshes/tube2.stl" scale="0.001 0.001 0.001" />
            </geometry>
            <material name="black" />
        </visual>
        <collision>
            <origin rpy="0 0 0" xyz="-0.000111 0.010041 -0.37059" />
            <geometry>
                <mesh filename="package://crisp_description/meshes/tube2.stl" scale="0.001 0.001 0.001" />
            </geometry>
        </collision>
    </link>
    <link name="crisp_2_wrist_link1">
        <inertial>
            <origin rpy="0 0 0" xyz="3.272677325775889e-07 0.0029345319652001097 -0.03169306675776801" />
            <mass value="0.2120397644725218" />
            <inertia ixx="0.000175" ixy="-0.0" ixz="0.0" iyy="0.00017" iyz="1.1e-05" izz="0.000139" />
        </inertial>
        <visual>
            <origin rpy="0 0 0" xyz="-0.000111 0.010041 -0.27959" />
            <geometry>
                <mesh filename="package://crisp_description/meshes/wrist_link1.stl" scale="0.001 0.001 0.001" />
            </geometry>
            <material name="silver" />
        </visual>
        <collision>
            <origin rpy="0 0 0" xyz="-0.000111 0.010041 -0.27959" />
            <geometry>
                <mesh filename="package://crisp_description/meshes/wrist_link1.stl" scale="0.001 0.001 0.001" />
            </geometry>
        </collision>
    </link>
    <link name="crisp_2_wrist_link2">
        <inertial>
            <origin rpy="0 0 0" xyz="3.2681919059462765e-07 0.034243790458059184 0.003213444605775856" />
            <mass value="0.17601570721446155" />
            <inertia ixx="0.000126" ixy="0.0" ixz="-0.0" iyy="0.000112" iyz="-8e-06" izz="0.000122" />
        </inertial>
        <visual>
            <origin rpy="0 0 0" xyz="-0.000111 -0.024859 -0.23859" />
            <geometry>
                <mesh filename="package://crisp_description/meshes/wrist_link2.stl" scale="0.001 0.001 0.001" />
            </geometry>
            <material name="silver" />
        </visual>
        <collision>
            <origin rpy="0 0 0" xyz="-0.000111 -0.024859 -0.23859" />
            <geometry>
                <mesh filename="package://crisp_description/meshes/wrist_link2.stl" scale="0.001 0.001 0.001" />
            </geometry>
        </collision>
    </link>
    <link name="crisp_2_wrist_link3">
        <inertial>
            <origin rpy="0 0 0" xyz="3.328659660357594e-07 0.003213090953286188 0.03424415588268198" />
            <mass value="0.17601599196961085" />
            <inertia ixx="0.000126" ixy="0.0" ixz="-0.0" iyy="0.000122" iyz="-8e-06" izz="0.000112" />
        </inertial>
        <visual>
            <origin rpy="0 0 0" xyz="-0.000111 -0.064859 -0.27349" />
            <geometry>
                <mesh filename="package://crisp_description/meshes/wrist_link3.stl" scale="0.001 0.001 0.001" />
            </geometry>
            <material name="silver" />
        </visual>
        <collision>
            <origin rpy="0 0 0" xyz="-0.000111 -0.064859 -0.27349" />
            <geometry>
                <mesh filename="package://crisp_description/meshes/wrist_link3.stl" scale="0.001 0.001 0.001" />
            </geometry>
        </collision>
    </link>
    <link name="crisp_2_ee_mount">
        <inertial>
            <origin rpy="0 0 0" xyz="3.3153611991382443e-07 0.0048156835739818354 6.80155745613753e-08" />
            <mass value="0.025997600599102062" />
            <inertia ixx="9e-06" ixy="0.0" ixz="-0.0" iyy="1.7e-05" iyz="0.0" izz="8e-06" />
        </inertial>
        <visual>
            <origin rpy="0 0 0" xyz="-0.000111 -0.099859 -0.31349" />
            <geometry>
                <mesh filename="package://crisp_description/meshes/ee_mount.stl" scale="0.001 0.001 0.001" />
            </geometry>
            <material name="silver" />
        </visual>
        <collision>
            <origin rpy="0 0 0" xyz="-0.000111 -0.099859 -0.31349" />
            <geometry>
                <mesh filename="package://crisp_description/meshes/ee_mount.stl" scale="0.001 0.001 0.001" />
            </geometry>
        </collision>
    </link>
    <joint name="crisp_2_j1" type="revolute">
        <origin rpy="0 0 0" xyz="0.000152 -4.1e-05 0.09" />
        <parent link="crisp_2_base_link" />
        <child link="crisp_2_shoulder_link" />
        <axis xyz="0.0 0.0 1.0" />
        <limit effort="9.2" lower="-6.283185307179586" upper="6.283185307179586" velocity="3.5" />
    </joint>
    <joint name="crisp_2_j2" type="revolute">
        <origin rpy="0 0 0" xyz="0.0 -0.06 0.05" />
        <parent link="crisp_2_shoulder_link" />
        <child link="crisp_2_shoulder_bend" />
        <axis xyz="0.0 -1.0 -0.0" />
        <limit effort="9.2" lower="-6.283185307179586" upper="6.283185307179586" velocity="3.5" />
    </joint>
    <joint name="crisp_2_Rigid 5" type="fixed">
        <origin rpy="0 0 0" xyz="0.0 -0.050001 0.062" />
        <parent link="crisp_2_shoulder_bend" />
        <child link="crisp_2_tube1" />
    </joint>
    <joint name="crisp_2_Rigid 6" type="fixed">
        <origin rpy="0 0 0" xyz="0.0 0.0 0.168" />
        <parent link="crisp_2_tube1" />
        <child link="crisp_2_elbow_link" />
    </joint>
    <joint name="crisp_2_j3" type="revolute">
        <origin rpy="0 0 0" xyz="0.0 0.060001 0.061801" />
        <parent link="crisp_2_elbow_link" />
        <child link="crisp_2_elbow_bend" />
        <axis xyz="-0.0 1.0 0.0" />
        <limit effort="9.2" lower="-6.283185307179586" upper="6.283185307179586" velocity="3.5" />
    </joint>
    <joint name="crisp_2_Rigid 8" type="fixed">
        <origin rpy="0 0 0" xyz="-4.1e-05 0.04 -0.061211" />
        <parent link="crisp_2_elbow_bend" />
        <child link="crisp_2_tube2" />
    </joint>
    <joint name="crisp_2_Rigid 9" type="fixed">
        <origin rpy="0 0 0" xyz="0.0 0.0 -0.091" />
        <parent link="crisp_2_tube2" />
        <child link="crisp_2_wrist_link1" />
    </joint>
    <joint name="crisp_2_j4" type="revolute">
        <origin rpy="0 0 0" xyz="0.0 0.0349 -0.041" />
        <parent link="crisp_2_wrist_link1" />
        <child link="crisp_2_wrist_link2" />
        <axis xyz="-0.0 1.0 0.0" />
        <limit effort="3.3" lower="-6.283185307179586" upper="6.283185307179586" velocity="3.2" />
    </joint>
    <joint name="crisp_2_j5" type="revolute">
        <origin rpy="0 0 0" xyz="0.0 0.04 0.0349" />
        <parent link="crisp_2_wrist_link2" />
        <child link="crisp_2_wrist_link3" />
        <axis xyz="-0.0 0.0 1.0" />
        <limit effort="3.3" lower="-6.283185307179586" upper="6.283185307179586" velocity="3.2" />
    </joint>
    <joint name="crisp_2_j6" type="revolute">
        <origin rpy="0 0 0" xyz="0.0 0.035 0.04" />
        <parent link="crisp_2_wrist_link3" />
        <child link="crisp_2_ee_mount" />
        <axis xyz="-0.0 -1.0 -0.0" />
        <limit effort="3.3" lower="-6.283185307179586" upper="6.283185307179586" velocity="3.2" />
    </joint>
    <!-- params="prefix joint_limited
      shoulder_pan_lower_limit:=${-pi}    shoulder_pan_upper_limit:=${pi}
      shoulder_lift_lower_limit:=${-pi}    shoulder_lift_upper_limit:=${pi}
      elbow_joint_lower_limit:=${-pi}    elbow_joint_upper_limit:=${pi}
      wrist_1_lower_limit:=${-pi}    wrist_1_upper_limit:=${pi}
      wrist_2_lower_limit:=${-pi}    wrist_2_upper_limit:=${pi}
      wrist_3_lower_limit:=${-pi}    wrist_3_upper_limit:=${pi}
      transmission_hw_interface:=hardware_interface/PositionJointInterface
      safety_limits:=false safety_pos_margin:=0.15
      safety_k_position:=20"> -->
    <link name="crisp_3_base_link">
        <inertial>
            <origin rpy="0 0 0" xyz="0.0001603944729273711 -0.0003290623427609323 0.040147411165435416" />
            <mass value="0.6779611564550755" />
            <inertia ixx="0.001015" ixy="1e-06" ixz="0.0" iyy="0.001028" iyz="-2e-06" izz="0.001154" />
        </inertial>
        <visual>
            <origin rpy="0 0 0" xyz="0 0 0" />
            <geometry>
                <mesh filename="package://crisp_description/meshes/base_link.stl" scale="0.001 0.001 0.001" />
            </geometry>
            <material name="silver" />
        </visual>
        <collision>
            <origin rpy="0 0 0" xyz="0 0 0" />
            <geometry>
                <mesh filename="package://crisp_description/meshes/base_link.stl" scale="0.001 0.001 0.001" />
            </geometry>
        </collision>
    </link>
    <link name="crisp_3_shoulder_link">
        <inertial>
            <origin rpy="0 0 0" xyz="4.0011390054304076e-06 -0.00961982769835694 0.045447590610113775" />
            <mass value="0.4336022449379255" />
            <inertia ixx="0.000648" ixy="-0.0" ixz="-1e-06" iyy="0.000565" iyz="4.1e-05" izz="0.000631" />
        </inertial>
        <visual>
            <origin rpy="0 0 0" xyz="-0.000152 4.1e-05 -0.09" />
            <geometry>
                <mesh filename="package://crisp_description/meshes/shoulder_link.stl" scale="0.001 0.001 0.001" />
            </geometry>
            <material name="silver" />
        </visual>
        <collision>
            <origin rpy="0 0 0" xyz="-0.000152 4.1e-05 -0.09" />
            <geometry>
                <mesh filename="package://crisp_description/meshes/shoulder_link.stl" scale="0.001 0.001 0.001" />
            </geometry>
        </collision>
    </link>
    <link name="crisp_3_shoulder_bend">
        <inertial>
            <origin rpy="0 0 0" xyz="-3.977242232601117e-06 -0.045711629373503385 0.012907149486671848" />
            <mass value="0.24798358553552216" />
            <inertia ixx="0.000406" ixy="-1e-06" ixz="-0.0" iyy="0.000397" iyz="2.6e-05" izz="0.00033" />
        </inertial>
        <visual>
            <origin rpy="0 0 0" xyz="-0.000152 0.060041 -0.14" />
            <geometry>
                <mesh filename="package://crisp_description/meshes/shoulder_bend.stl" scale="0.001 0.001 0.001" />
            </geometry>
            <material name="silver" />
        </visual>
        <collision>
            <origin rpy="0 0 0" xyz="-0.000152 0.060041 -0.14" />
            <geometry>
                <mesh filename="package://crisp_description/meshes/shoulder_bend.stl" scale="0.001 0.001 0.001" />
            </geometry>
        </collision>
    </link>
    <link name="crisp_3_tube1">
        <inertial>
            <origin rpy="0 0 0" xyz="-1.218023921678265e-07 4.832804545162883e-07 0.08400037920452025" />
            <mass value="0.1359760217281118" />
            <inertia ixx="0.000423" ixy="-0.0" ixz="0.0" iyy="0.000423" iyz="0.0" izz="0.000207" />
        </inertial>
        <visual>
            <origin rpy="0 0 0" xyz="-0.000152 0.110042 -0.202" />
            <geometry>
                <mesh filename="package://crisp_description/meshes/tube1.stl" scale="0.001 0.001 0.001" />
            </geometry>
            <material name="black" />
        </visual>
        <collision>
            <origin rpy="0 0 0" xyz="-0.000152 0.110042 -0.202" />
            <geometry>
                <mesh filename="package://crisp_description/meshes/tube1.stl" scale="0.001 0.001 0.001" />
            </geometry>
        </collision>
    </link>
    <link name="crisp_3_elbow_link">
        <inertial>
            <origin rpy="0 0 0" xyz="-3.6405482122238116e-06 0.00835316151743537 0.05001631857596067" />
            <mass value="0.5160292603397482" />
            <inertia ixx="0.000905" ixy="1e-06" ixz="1e-06" iyy="0.000814" iyz="-7.4e-05" izz="0.000756" />
        </inertial>
        <visual>
            <origin rpy="0 0 0" xyz="-0.000152 0.110042 -0.37" />
            <geometry>
                <mesh filename="package://crisp_description/meshes/elbow_link.stl" scale="0.001 0.001 0.001" />
            </geometry>
            <material name="silver" />
        </visual>
        <collision>
            <origin rpy="0 0 0" xyz="-0.000152 0.110042 -0.37" />
            <geometry>
                <mesh filename="package://crisp_description/meshes/elbow_link.stl" scale="0.001 0.001 0.001" />
            </geometry>
        </collision>
    </link>
    <link name="crisp_3_elbow_bend">
        <inertial>
            <origin rpy="0 0 0" xyz="-4.075344323087168e-05 0.03327969273841646 -0.01030636733035839" />
            <mass value="0.16999673358161876" />
            <inertia ixx="0.000221" ixy="-0.0" ixz="0.0" iyy="0.000236" iyz="1.7e-05" izz="0.000146" />
        </inertial>
        <visual>
            <origin rpy="0 0 0" xyz="-0.000152 0.050041 -0.431801" />
            <geometry>
                <mesh filename="package://crisp_description/meshes/elbow_bend.stl" scale="0.001 0.001 0.001" />
            </geometry>
            <material name="silver" />
        </visual>
        <collision>
            <origin rpy="0 0 0" xyz="-0.000152 0.050041 -0.431801" />
            <geometry>
                <mesh filename="package://crisp_description/meshes/elbow_bend.stl" scale="0.001 0.001 0.001" />
            </geometry>
        </collision>
    </link>
    <link name="crisp_3_tube2">
        <inertial>
            <origin rpy="0 0 0" xyz="3.31534666480639e-07 -2.8192269833048067e-07 -0.04549993912254768" />
            <mass value="0.035999481079213504" />
            <inertia ixx="3.5e-05" ixy="0.0" ixz="0.0" iyy="3.5e-05" iyz="0.0" izz="2.1e-05" />
        </inertial>
        <visual>
            <origin rpy="0 0 0" xyz="-0.000111 0.010041 -0.37059" />
            <geometry>
                <mesh filename="package://crisp_description/meshes/tube2.stl" scale="0.001 0.001 0.001" />
            </geometry>
            <material name="black" />
        </visual>
        <collision>
            <origin rpy="0 0 0" xyz="-0.000111 0.010041 -0.37059" />
            <geometry>
                <mesh filename="package://crisp_description/meshes/tube2.stl" scale="0.001 0.001 0.001" />
            </geometry>
        </collision>
    </link>
    <link name="crisp_3_wrist_link1">
        <inertial>
            <origin rpy="0 0 0" xyz="3.272677325775889e-07 0.0029345319652001097 -0.03169306675776801" />
            <mass value="0.2120397644725218" />
            <inertia ixx="0.000175" ixy="-0.0" ixz="0.0" iyy="0.00017" iyz="1.1e-05" izz="0.000139" />
        </inertial>
        <visual>
            <origin rpy="0 0 0" xyz="-0.000111 0.010041 -0.27959" />
            <geometry>
                <mesh filename="package://crisp_description/meshes/wrist_link1.stl" scale="0.001 0.001 0.001" />
            </geometry>
            <material name="silver" />
        </visual>
        <collision>
            <origin rpy="0 0 0" xyz="-0.000111 0.010041 -0.27959" />
            <geometry>
                <mesh filename="package://crisp_description/meshes/wrist_link1.stl" scale="0.001 0.001 0.001" />
            </geometry>
        </collision>
    </link>
    <link name="crisp_3_wrist_link2">
        <inertial>
            <origin rpy="0 0 0" xyz="3.2681919059462765e-07 0.034243790458059184 0.003213444605775856" />
            <mass value="0.17601570721446155" />
            <inertia ixx="0.000126" ixy="0.0" ixz="-0.0" iyy="0.000112" iyz="-8e-06" izz="0.000122" />
        </inertial>
        <visual>
            <origin rpy="0 0 0" xyz="-0.000111 -0.024859 -0.23859" />
            <geometry>
                <mesh filename="package://crisp_description/meshes/wrist_link2.stl" scale="0.001 0.001 0.001" />
            </geometry>
            <material name="silver" />
        </visual>
        <collision>
            <origin rpy="0 0 0" xyz="-0.000111 -0.024859 -0.23859" />
            <geometry>
                <mesh filename="package://crisp_description/meshes/wrist_link2.stl" scale="0.001 0.001 0.001" />
            </geometry>
        </collision>
    </link>
    <link name="crisp_3_wrist_link3">
        <inertial>
            <origin rpy="0 0 0" xyz="3.328659660357594e-07 0.003213090953286188 0.03424415588268198" />
            <mass value="0.17601599196961085" />
            <inertia ixx="0.000126" ixy="0.0" ixz="-0.0" iyy="0.000122" iyz="-8e-06" izz="0.000112" />
        </inertial>
        <visual>
            <origin rpy="0 0 0" xyz="-0.000111 -0.064859 -0.27349" />
            <geometry>
                <mesh filename="package://crisp_description/meshes/wrist_link3.stl" scale="0.001 0.001 0.001" />
            </geometry>
            <material name="silver" />
        </visual>
        <collision>
            <origin rpy="0 0 0" xyz="-0.000111 -0.064859 -0.27349" />
            <geometry>
                <mesh filename="package://crisp_description/meshes/wrist_link3.stl" scale="0.001 0.001 0.001" />
            </geometry>
        </collision>
    </link>
    <link name="crisp_3_ee_mount">
        <inertial>
            <origin rpy="0 0 0" xyz="3.3153611991382443e-07 0.0048156835739818354 6.80155745613753e-08" />
            <mass value="0.025997600599102062" />
            <inertia ixx="9e-06" ixy="0.0" ixz="-0.0" iyy="1.7e-05" iyz="0.0" izz="8e-06" />
        </inertial>
        <visual>
            <origin rpy="0 0 0" xyz="-0.000111 -0.099859 -0.31349" />
            <geometry>
                <mesh filename="package://crisp_description/meshes/ee_mount.stl" scale="0.001 0.001 0.001" />
            </geometry>
            <material name="silver" />
        </visual>
        <collision>
            <origin rpy="0 0 0" xyz="-0.000111 -0.099859 -0.31349" />
            <geometry>
                <mesh filename="package://crisp_description/meshes/ee_mount.stl" scale="0.001 0.001 0.001" />
            </geometry>
        </collision>
    </link>
    <joint name="crisp_3_j1" type="revolute">
        <origin rpy="0 0 0" xyz="0.000152 -4.1e-05 0.09" />
        <parent link="crisp_3_base_link" />
        <child link="crisp_3_shoulder_link" />
        <axis xyz="0.0 0.0 1.0" />
        <limit effort="9.2" lower="-6.283185307179586" upper="6.283185307179586" velocity="3.5" />
    </joint>
    <joint name="crisp_3_j2" type="revolute">
        <origin rpy="0 0 0" xyz="0.0 -0.06 0.05" />
        <parent link="crisp_3_shoulder_link" />
        <child link="crisp_3_shoulder_bend" />
        <axis xyz="0.0 -1.0 -0.0" />
        <limit effort="9.2" lower="-6.283185307179586" upper="6.283185307179586" velocity="3.5" />
    </joint>
    <joint name="crisp_3_Rigid 5" type="fixed">
        <origin rpy="0 0 0" xyz="0.0 -0.050001 0.062" />
        <parent link="crisp_3_shoulder_bend" />
        <child link="crisp_3_tube1" />
    </joint>
    <joint name="crisp_3_Rigid 6" type="fixed">
        <origin rpy="0 0 0" xyz="0.0 0.0 0.168" />
        <parent link="crisp_3_tube1" />
        <child link="crisp_3_elbow_link" />
    </joint>
    <joint name="crisp_3_j3" type="revolute">
        <origin rpy="0 0 0" xyz="0.0 0.060001 0.061801" />
        <parent link="crisp_3_elbow_link" />
        <child link="crisp_3_elbow_bend" />
        <axis xyz="-0.0 1.0 0.0" />
        <limit effort="9.2" lower="-6.283185307179586" upper="6.283185307179586" velocity="3.5" />
    </joint>
    <joint name="crisp_3_Rigid 8" type="fixed">
        <origin rpy="0 0 0" xyz="-4.1e-05 0.04 -0.061211" />
        <parent link="crisp_3_elbow_bend" />
        <child link="crisp_3_tube2" />
    </joint>
    <joint name="crisp_3_Rigid 9" type="fixed">
        <origin rpy="0 0 0" xyz="0.0 0.0 -0.091" />
        <parent link="crisp_3_tube2" />
        <child link="crisp_3_wrist_link1" />
    </joint>
    <joint name="crisp_3_j4" type="revolute">
        <origin rpy="0 0 0" xyz="0.0 0.0349 -0.041" />
        <parent link="crisp_3_wrist_link1" />
        <child link="crisp_3_wrist_link2" />
        <axis xyz="-0.0 1.0 0.0" />
        <limit effort="3.3" lower="-6.283185307179586" upper="6.283185307179586" velocity="3.2" />
    </joint>
    <joint name="crisp_3_j5" type="revolute">
        <origin rpy="0 0 0" xyz="0.0 0.04 0.0349" />
        <parent link="crisp_3_wrist_link2" />
        <child link="crisp_3_wrist_link3" />
        <axis xyz="-0.0 0.0 1.0" />
        <limit effort="3.3" lower="-6.283185307179586" upper="6.283185307179586" velocity="3.2" />
    </joint>
    <joint name="crisp_3_j6" type="revolute">
        <origin rpy="0 0 0" xyz="0.0 0.035 0.04" />
        <parent link="crisp_3_wrist_link3" />
        <child link="crisp_3_ee_mount" />
        <axis xyz="-0.0 -1.0 -0.0" />
        <limit effort="3.3" lower="-6.283185307179586" upper="6.283185307179586" velocity="3.2" />
    </joint>
    <!-- params="prefix joint_limited
      shoulder_pan_lower_limit:=${-pi}    shoulder_pan_upper_limit:=${pi}
      shoulder_lift_lower_limit:=${-pi}    shoulder_lift_upper_limit:=${pi}
      elbow_joint_lower_limit:=${-pi}    elbow_joint_upper_limit:=${pi}
      wrist_1_lower_limit:=${-pi}    wrist_1_upper_limit:=${pi}
      wrist_2_lower_limit:=${-pi}    wrist_2_upper_limit:=${pi}
      wrist_3_lower_limit:=${-pi}    wrist_3_upper_limit:=${pi}
      transmission_hw_interface:=hardware_interface/PositionJointInterface
      safety_limits:=false safety_pos_margin:=0.15
      safety_k_position:=20"> -->
    <link name="crisp_4_base_link">
        <inertial>
            <origin rpy="0 0 0" xyz="0.0001603944729273711 -0.0003290623427609323 0.040147411165435416" />
            <mass value="0.6779611564550755" />
            <inertia ixx="0.001015" ixy="1e-06" ixz="0.0" iyy="0.001028" iyz="-2e-06" izz="0.001154" />
        </inertial>
        <visual>
            <origin rpy="0 0 0" xyz="0 0 0" />
            <geometry>
                <mesh filename="package://crisp_description/meshes/base_link.stl" scale="0.001 0.001 0.001" />
            </geometry>
            <material name="silver" />
        </visual>
        <collision>
            <origin rpy="0 0 0" xyz="0 0 0" />
            <geometry>
                <mesh filename="package://crisp_description/meshes/base_link.stl" scale="0.001 0.001 0.001" />
            </geometry>
        </collision>
    </link>
    <link name="crisp_4_shoulder_link">
        <inertial>
            <origin rpy="0 0 0" xyz="4.0011390054304076e-06 -0.00961982769835694 0.045447590610113775" />
            <mass value="0.4336022449379255" />
            <inertia ixx="0.000648" ixy="-0.0" ixz="-1e-06" iyy="0.000565" iyz="4.1e-05" izz="0.000631" />
        </inertial>
        <visual>
            <origin rpy="0 0 0" xyz="-0.000152 4.1e-05 -0.09" />
            <geometry>
                <mesh filename="package://crisp_description/meshes/shoulder_link.stl" scale="0.001 0.001 0.001" />
            </geometry>
            <material name="silver" />
        </visual>
        <collision>
            <origin rpy="0 0 0" xyz="-0.000152 4.1e-05 -0.09" />
            <geometry>
                <mesh filename="package://crisp_description/meshes/shoulder_link.stl" scale="0.001 0.001 0.001" />
            </geometry>
        </collision>
    </link>
    <link name="crisp_4_shoulder_bend">
        <inertial>
            <origin rpy="0 0 0" xyz="-3.977242232601117e-06 -0.045711629373503385 0.012907149486671848" />
            <mass value="0.24798358553552216" />
            <inertia ixx="0.000406" ixy="-1e-06" ixz="-0.0" iyy="0.000397" iyz="2.6e-05" izz="0.00033" />
        </inertial>
        <visual>
            <origin rpy="0 0 0" xyz="-0.000152 0.060041 -0.14" />
            <geometry>
                <mesh filename="package://crisp_description/meshes/shoulder_bend.stl" scale="0.001 0.001 0.001" />
            </geometry>
            <material name="silver" />
        </visual>
        <collision>
            <origin rpy="0 0 0" xyz="-0.000152 0.060041 -0.14" />
            <geometry>
                <mesh filename="package://crisp_description/meshes/shoulder_bend.stl" scale="0.001 0.001 0.001" />
            </geometry>
        </collision>
    </link>
    <link name="crisp_4_tube1">
        <inertial>
            <origin rpy="0 0 0" xyz="-1.218023921678265e-07 4.832804545162883e-07 0.08400037920452025" />
            <mass value="0.1359760217281118" />
            <inertia ixx="0.000423" ixy="-0.0" ixz="0.0" iyy="0.000423" iyz="0.0" izz="0.000207" />
        </inertial>
        <visual>
            <origin rpy="0 0 0" xyz="-0.000152 0.110042 -0.202" />
            <geometry>
                <mesh filename="package://crisp_description/meshes/tube1.stl" scale="0.001 0.001 0.001" />
            </geometry>
            <material name="black" />
        </visual>
        <collision>
            <origin rpy="0 0 0" xyz="-0.000152 0.110042 -0.202" />
            <geometry>
                <mesh filename="package://crisp_description/meshes/tube1.stl" scale="0.001 0.001 0.001" />
            </geometry>
        </collision>
    </link>
    <link name="crisp_4_elbow_link">
        <inertial>
            <origin rpy="0 0 0" xyz="-3.6405482122238116e-06 0.00835316151743537 0.05001631857596067" />
            <mass value="0.5160292603397482" />
            <inertia ixx="0.000905" ixy="1e-06" ixz="1e-06" iyy="0.000814" iyz="-7.4e-05" izz="0.000756" />
        </inertial>
        <visual>
            <origin rpy="0 0 0" xyz="-0.000152 0.110042 -0.37" />
            <geometry>
                <mesh filename="package://crisp_description/meshes/elbow_link.stl" scale="0.001 0.001 0.001" />
            </geometry>
            <material name="silver" />
        </visual>
        <collision>
            <origin rpy="0 0 0" xyz="-0.000152 0.110042 -0.37" />
            <geometry>
                <mesh filename="package://crisp_description/meshes/elbow_link.stl" scale="0.001 0.001 0.001" />
            </geometry>
        </collision>
    </link>
    <link name="crisp_4_elbow_bend">
        <inertial>
            <origin rpy="0 0 0" xyz="-4.075344323087168e-05 0.03327969273841646 -0.01030636733035839" />
            <mass value="0.16999673358161876" />
            <inertia ixx="0.000221" ixy="-0.0" ixz="0.0" iyy="0.000236" iyz="1.7e-05" izz="0.000146" />
        </inertial>
        <visual>
            <origin rpy="0 0 0" xyz="-0.000152 0.050041 -0.431801" />
            <geometry>
                <mesh filename="package://crisp_description/meshes/elbow_bend.stl" scale="0.001 0.001 0.001" />
            </geometry>
            <material name="silver" />
        </visual>
        <collision>
            <origin rpy="0 0 0" xyz="-0.000152 0.050041 -0.431801" />
            <geometry>
                <mesh filename="package://crisp_description/meshes/elbow_bend.stl" scale="0.001 0.001 0.001" />
            </geometry>
        </collision>
    </link>
    <link name="crisp_4_tube2">
        <inertial>
            <origin rpy="0 0 0" xyz="3.31534666480639e-07 -2.8192269833048067e-07 -0.04549993912254768" />
            <mass value="0.035999481079213504" />
            <inertia ixx="3.5e-05" ixy="0.0" ixz="0.0" iyy="3.5e-05" iyz="0.0" izz="2.1e-05" />
        </inertial>
        <visual>
            <origin rpy="0 0 0" xyz="-0.000111 0.010041 -0.37059" />
            <geometry>
                <mesh filename="package://crisp_description/meshes/tube2.stl" scale="0.001 0.001 0.001" />
            </geometry>
            <material name="black" />
        </visual>
        <collision>
            <origin rpy="0 0 0" xyz="-0.000111 0.010041 -0.37059" />
            <geometry>
                <mesh filename="package://crisp_description/meshes/tube2.stl" scale="0.001 0.001 0.001" />
            </geometry>
        </collision>
    </link>
    <link name="crisp_4_wrist_link1">
        <inertial>
            <origin rpy="0 0 0" xyz="3.272677325775889e-07 0.0029345319652001097 -0.03169306675776801" />
            <mass value="0.2120397644725218" />
            <inertia ixx="0.000175" ixy="-0.0" ixz="0.0" iyy="0.00017" iyz="1.1e-05" izz="0.000139" />
        </inertial>
        <visual>
            <origin rpy="0 0 0" xyz="-0.000111 0.010041 -0.27959" />
            <geometry>
                <mesh filename="package://crisp_description/meshes/wrist_link1.stl" scale="0.001 0.001 0.001" />
            </geometry>
            <material name="silver" />
        </visual>
        <collision>
            <origin rpy="0 0 0" xyz="-0.000111 0.010041 -0.27959" />
            <geometry>
                <mesh filename="package://crisp_description/meshes/wrist_link1.stl" scale="0.001 0.001 0.001" />
            </geometry>
        </collision>
    </link>
    <link name="crisp_4_wrist_link2">
        <inertial>
            <origin rpy="0 0 0" xyz="3.2681919059462765e-07 0.034243790458059184 0.003213444605775856" />
            <mass value="0.17601570721446155" />
            <inertia ixx="0.000126" ixy="0.0" ixz="-0.0" iyy="0.000112" iyz="-8e-06" izz="0.000122" />
        </inertial>
        <visual>
            <origin rpy="0 0 0" xyz="-0.000111 -0.024859 -0.23859" />
            <geometry>
                <mesh filename="package://crisp_description/meshes/wrist_link2.stl" scale="0.001 0.001 0.001" />
            </geometry>
            <material name="silver" />
        </visual>
        <collision>
            <origin rpy="0 0 0" xyz="-0.000111 -0.024859 -0.23859" />
            <geometry>
                <mesh filename="package://crisp_description/meshes/wrist_link2.stl" scale="0.001 0.001 0.001" />
            </geometry>
        </collision>
    </link>
    <link name="crisp_4_wrist_link3">
        <inertial>
            <origin rpy="0 0 0" xyz="3.328659660357594e-07 0.003213090953286188 0.03424415588268198" />
            <mass value="0.17601599196961085" />
            <inertia ixx="0.000126" ixy="0.0" ixz="-0.0" iyy="0.000122" iyz="-8e-06" izz="0.000112" />
        </inertial>
        <visual>
            <origin rpy="0 0 0" xyz="-0.000111 -0.064859 -0.27349" />
            <geometry>
                <mesh filename="package://crisp_description/meshes/wrist_link3.stl" scale="0.001 0.001 0.001" />
            </geometry>
            <material name="silver" />
        </visual>
        <collision>
            <origin rpy="0 0 0" xyz="-0.000111 -0.064859 -0.27349" />
            <geometry>
                <mesh filename="package://crisp_description/meshes/wrist_link3.stl" scale="0.001 0.001 0.001" />
            </geometry>
        </collision>
    </link>
    <link name="crisp_4_ee_mount">
        <inertial>
            <origin rpy="0 0 0" xyz="3.3153611991382443e-07 0.0048156835739818354 6.80155745613753e-08" />
            <mass value="0.025997600599102062" />
            <inertia ixx="9e-06" ixy="0.0" ixz="-0.0" iyy="1.7e-05" iyz="0.0" izz="8e-06" />
        </inertial>
        <visual>
            <origin rpy="0 0 0" xyz="-0.000111 -0.099859 -0.31349" />
            <geometry>
                <mesh filename="package://crisp_description/meshes/ee_mount.stl" scale="0.001 0.001 0.001" />
            </geometry>
            <material name="silver" />
        </visual>
        <collision>
            <origin rpy="0 0 0" xyz="-0.000111 -0.099859 -0.31349" />
            <geometry>
                <mesh filename="package://crisp_description/meshes/ee_mount.stl" scale="0.001 0.001 0.001" />
            </geometry>
        </collision>
    </link>
    <joint name="crisp_4_j1" type="revolute">
        <origin rpy="0 0 0" xyz="0.000152 -4.1e-05 0.09" />
        <parent link="crisp_4_base_link" />
        <child link="crisp_4_shoulder_link" />
        <axis xyz="0.0 0.0 1.0" />
        <limit effort="9.2" lower="-6.283185307179586" upper="6.283185307179586" velocity="3.5" />
    </joint>
    <joint name="crisp_4_j2" type="revolute">
        <origin rpy="0 0 0" xyz="0.0 -0.06 0.05" />
        <parent link="crisp_4_shoulder_link" />
        <child link="crisp_4_shoulder_bend" />
        <axis xyz="0.0 -1.0 -0.0" />
        <limit effort="9.2" lower="-6.283185307179586" upper="6.283185307179586" velocity="3.5" />
    </joint>
    <joint name="crisp_4_Rigid 5" type="fixed">
        <origin rpy="0 0 0" xyz="0.0 -0.050001 0.062" />
        <parent link="crisp_4_shoulder_bend" />
        <child link="crisp_4_tube1" />
    </joint>
    <joint name="crisp_4_Rigid 6" type="fixed">
        <origin rpy="0 0 0" xyz="0.0 0.0 0.168" />
        <parent link="crisp_4_tube1" />
        <child link="crisp_4_elbow_link" />
    </joint>
    <joint name="crisp_4_j3" type="revolute">
        <origin rpy="0 0 0" xyz="0.0 0.060001 0.061801" />
        <parent link="crisp_4_elbow_link" />
        <child link="crisp_4_elbow_bend" />
        <axis xyz="-0.0 1.0 0.0" />
        <limit effort="9.2" lower="-6.283185307179586" upper="6.283185307179586" velocity="3.5" />
    </joint>
    <joint name="crisp_4_Rigid 8" type="fixed">
        <origin rpy="0 0 0" xyz="-4.1e-05 0.04 -0.061211" />
        <parent link="crisp_4_elbow_bend" />
        <child link="crisp_4_tube2" />
    </joint>
    <joint name="crisp_4_Rigid 9" type="fixed">
        <origin rpy="0 0 0" xyz="0.0 0.0 -0.091" />
        <parent link="crisp_4_tube2" />
        <child link="crisp_4_wrist_link1" />
    </joint>
    <joint name="crisp_4_j4" type="revolute">
        <origin rpy="0 0 0" xyz="0.0 0.0349 -0.041" />
        <parent link="crisp_4_wrist_link1" />
        <child link="crisp_4_wrist_link2" />
        <axis xyz="-0.0 1.0 0.0" />
        <limit effort="3.3" lower="-6.283185307179586" upper="6.283185307179586" velocity="3.2" />
    </joint>
    <joint name="crisp_4_j5" type="revolute">
        <origin rpy="0 0 0" xyz="0.0 0.04 0.0349" />
        <parent link="crisp_4_wrist_link2" />
        <child link="crisp_4_wrist_link3" />
        <axis xyz="-0.0 0.0 1.0" />
        <limit effort="3.3" lower="-6.283185307179586" upper="6.283185307179586" velocity="3.2" />
    </joint>
    <joint name="crisp_4_j6" type="revolute">
        <origin rpy="0 0 0" xyz="0.0 0.035 0.04" />
        <parent link="crisp_4_wrist_link3" />
        <child link="crisp_4_ee_mount" />
        <axis xyz="-0.0 -1.0 -0.0" />
        <limit effort="3.3" lower="-6.283185307179586" upper="6.283185307179586" velocity="3.2" />
    </joint>
    // Base for robots
    <!-- start of conveyor base description-->
    <!-- start of conveyor base description-->
    <!-- start of conveyor base description-->
    <link name="world" />
    <!-- box shaped Conveyor -->
    <link name="conveyor">
        <visual>
            <origin rpy="0 0 0" xyz="0 0 0.453" />
            <geometry>
                <box size=".565 2 .906" />
            </geometry>
            <material name="Blue">
                <color rgba="0.0 0.0 0.9 1.0" />
            </material>
        </visual>
        <collision>
            <origin rpy="0 0 0" xyz="0 0 0.453" />
            <geometry>
                <box size=".565 2 .906" />
            </geometry>
        </collision>
        <inertial>
            <origin rpy="0.0 0.0 0.0" xyz="0.0 0.0 0.0" />
            <mass value="100.0" />
            <inertia ixx="0.001" ixy="0.0" ixz="0.001" iyy="0.0" iyz="0.0" izz="0.001" />
        </inertial>
    </link>
    <joint name="conveyor_to_world" type="fixed">
        <parent link="world" />
        <child link="conveyor" />
        <origin rpy="0.0 0.0 0.0" xyz="0.0 0.0 0.0" />
    </joint>
    <!-- box shaped mount as base for the Crisp Arm 1 -->
    <link name="base1">
        <visual>
            <origin rpy="0 0 0" xyz="0.3475 0.750 0.881" />
            <geometry>
                <box size=".13 .13 .05" />
            </geometry>
            <material name="Red">
                <color rgba="0.9 0.0 0.0 1.0" />
            </material>
        </visual>
        <collision>
            <origin rpy="0 0 0" xyz="0.3475 0.750 0.881" />
            <geometry>
                <box size="0.13 0.13 0.05" />
            </geometry>
        </collision>
        <inertial>
            <origin rpy="0.0 0.0 0.0" xyz="0.0 0.0 0.0" />
            <mass value="5" />
            <inertia ixx="0.001" ixy="0.0" ixz="0.001" iyy="0.0" iyz="0.0" izz="0.001" />
        </inertial>
    </link>
    <joint name="base1_to_conveyor" type="fixed">
        <parent link="conveyor" />
        <child link="base1" />
        <origin rpy="0.0 0.0 0.0" xyz="0.0 0.0 0.0" />
    </joint>
    <!-- box shaped mount as base for the Crisp Arm 2 -->
    <link name="base2">
        <visual>
            <origin rpy="0 0 0" xyz="0.3475 -0.250 0.881" />
            <geometry>
                <box size=".13 .13 .05" />
            </geometry>
            <material name="Red">
                <color rgba="0.9 0.0 0.0 1.0" />
            </material>
        </visual>
        <collision>
            <origin rpy="0 0 0" xyz="0.3475 -0.250 0.881" />
            <geometry>
                <box size="0.13 0.13 0.05" />
            </geometry>
        </collision>
        <inertial>
            <origin rpy="0.0 0.0 0.0" xyz="0.0 0.0 0.0" />
            <mass value="5" />
            <inertia ixx="0.001" ixy="0.0" ixz="0.001" iyy="0.0" iyz="0.0" izz="0.001" />
        </inertial>
    </link>
    <joint name="base2_to_conveyor" type="fixed">
        <parent link="conveyor" />
        <child link="base2" />
        <origin rpy="0.0 0.0 0.0" xyz="0.0 0.0 0.0" />
    </joint>
    <!-- box shaped mount as base for the Crisp Arm 3 -->
    <link name="base3">
        <visual>
            <origin rpy="0 0 0" xyz="-0.3475 0.250 0.881" />
            <geometry>
                <box size=".13 .13 .05" />
            </geometry>
            <material name="Red">
                <color rgba="0.9 0.0 0.0 1.0" />
            </material>
        </visual>
        <collision>
            <origin rpy="0 0 0" xyz="-0.3475 0.250 0.881" />
            <geometry>
                <box size="0.13 0.13 0.05" />
            </geometry>
        </collision>
        <inertial>
            <origin rpy="0.0 0.0 0.0" xyz="0.0 0.0 0.0" />
            <mass value="5" />
            <inertia ixx="0.001" ixy="0.0" ixz="0.001" iyy="0.0" iyz="0.0" izz="0.001" />
        </inertial>
    </link>
    <joint name="base3_to_conveyor" type="fixed">
        <parent link="conveyor" />
        <child link="base3" />
        <origin rpy="0.0 0.0 0.0" xyz="0.0 0.0 0.0" />
    </joint>
    <!-- box shaped mount as base for the Crisp Arm 4 -->
    <link name="base4">
        <visual>
            <origin rpy="0 0 0" xyz="-0.3475 -0.750 0.881" />
            <geometry>
                <box size=".13 .13 .05" />
            </geometry>
            <material name="Red">
                <color rgba="0.9 0.0 0.0 1.0" />
            </material>
        </visual>
        <collision>
            <origin rpy="0 0 0" xyz="-0.3475 -0.750 0.881" />
            <geometry>
                <box size="0.13 0.13 0.05" />
            </geometry>
        </collision>
        <inertial>
            <origin rpy="0.0 0.0 0.0" xyz="0.0 0.0 0.0" />
            <mass value="5" />
            <inertia ixx="0.001" ixy="0.0" ixz="0.001" iyy="0.0" iyz="0.0" izz="0.001" />
        </inertial>
    </link>
    <joint name="base4_to_conveyor" type="fixed">
        <parent link="conveyor" />
        <child link="base4" />
        <origin rpy="0.0 0.0 0.0" xyz="0.0 0.0 0.0" />
    </joint>
    <!-- end of conveyor base description-->
    <!-- end of conveyor base description-->
    <!-- end of conveyor base description-->
    // Add Proper links and Joints to World Frame and multiple arms
    <joint name="world_arm_1" type="fixed">
        <parent link="base1" />
        <child link="crisp_1_base_link" />
        <origin rpy="0.0 0.0 1.57" xyz="0.3475 0.750 0.906" />
    </joint>
    <joint name="world_arm_2" type="fixed">
        <parent link="base2" />
        <child link="crisp_2_base_link" />
        <origin rpy="0.0 0.0 1.57" xyz="0.3475 -0.250 .906" />
    </joint>
    <joint name="world_arm_3" type="fixed">
        <parent link="base3" />
        <child link="crisp_3_base_link" />
        <origin rpy="0.0 0.0 1.57" xyz="-0.3475 0.250 0.906" />
    </joint>
    <joint name="world_arm_4" type="fixed">
        <parent link="base4" />
        <child link="crisp_4_base_link" />
        <origin rpy="0.0 0.0 1.57" xyz="-0.3475 -0.750 .906" />
    </joint>
    <transmission name="trans_crisp_1_j1">
        <type>transmission_interface/SimpleTransmission</type>
        <joint name="crisp_1_j1">
            <hardwareInterface>hardware_interface/EffortJointInterface</hardwareInterface>
        </joint>
        <actuator name="crisp_1_j1_motor">
            <hardwareInterface>hardware_interface/EffortJointInterface</hardwareInterface>
            <mechanicalReduction>1</mechanicalReduction>
        </actuator>
    </transmission>
    <transmission name="trans_crisp_1_j2">
        <type>transmission_interface/SimpleTransmission</type>
        <joint name="crisp_1_j2">
            <hardwareInterface>hardware_interface/EffortJointInterface</hardwareInterface>
        </joint>
        <actuator name="crisp_1_j2_motor">
            <hardwareInterface>hardware_interface/EffortJointInterface</hardwareInterface>
            <mechanicalReduction>1</mechanicalReduction>
        </actuator>
    </transmission>
    <transmission name="trans_crisp_1_j3">
        <type>transmission_interface/SimpleTransmission</type>
        <joint name="crisp_1_j3">
            <hardwareInterface>hardware_interface/EffortJointInterface</hardwareInterface>
        </joint>
        <actuator name="crisp_1_j3_motor">
            <hardwareInterface>hardware_interface/EffortJointInterface</hardwareInterface>
            <mechanicalReduction>1</mechanicalReduction>
        </actuator>
    </transmission>
    <transmission name="trans_crisp_1_j4">
        <type>transmission_interface/SimpleTransmission</type>
        <joint name="crisp_1_j4">
            <hardwareInterface>hardware_interface/EffortJointInterface</hardwareInterface>
        </joint>
        <actuator name="crisp_1_j4_motor">
            <hardwareInterface>hardware_interface/EffortJointInterface</hardwareInterface>
            <mechanicalReduction>1</mechanicalReduction>
        </actuator>
    </transmission>
    <transmission name="trans_crisp_1_j5">
        <type>transmission_interface/SimpleTransmission</type>
        <joint name="crisp_1_j5">
            <hardwareInterface>hardware_interface/EffortJointInterface</hardwareInterface>
        </joint>
        <actuator name="crisp_1_j5_motor">
            <hardwareInterface>hardware_interface/EffortJointInterface</hardwareInterface>
            <mechanicalReduction>1</mechanicalReduction>
        </actuator>
    </transmission>
    <transmission name="trans_crisp_1_j6">
        <type>transmission_interface/SimpleTransmission</type>
        <joint name="crisp_1_j6">
            <hardwareInterface>hardware_interface/EffortJointInterface</hardwareInterface>
        </joint>
        <actuator name="crisp_1_j6_motor">
            <hardwareInterface>hardware_interface/EffortJointInterface</hardwareInterface>
            <mechanicalReduction>1</mechanicalReduction>
        </actuator>
    </transmission>
    <transmission name="trans_crisp_2_j1">
        <type>transmission_interface/SimpleTransmission</type>
        <joint name="crisp_2_j1">
            <hardwareInterface>hardware_interface/EffortJointInterface</hardwareInterface>
        </joint>
        <actuator name="crisp_2_j1_motor">
            <hardwareInterface>hardware_interface/EffortJointInterface</hardwareInterface>
            <mechanicalReduction>1</mechanicalReduction>
        </actuator>
    </transmission>
    <transmission name="trans_crisp_2_j2">
        <type>transmission_interface/SimpleTransmission</type>
        <joint name="crisp_2_j2">
            <hardwareInterface>hardware_interface/EffortJointInterface</hardwareInterface>
        </joint>
        <actuator name="crisp_2_j2_motor">
            <hardwareInterface>hardware_interface/EffortJointInterface</hardwareInterface>
            <mechanicalReduction>1</mechanicalReduction>
        </actuator>
    </transmission>
    <transmission name="trans_crisp_2_j3">
        <type>transmission_interface/SimpleTransmission</type>
        <joint name="crisp_2_j3">
            <hardwareInterface>hardware_interface/EffortJointInterface</hardwareInterface>
        </joint>
        <actuator name="crisp_2_j3_motor">
            <hardwareInterface>hardware_interface/EffortJointInterface</hardwareInterface>
            <mechanicalReduction>1</mechanicalReduction>
        </actuator>
    </transmission>
    <transmission name="trans_crisp_2_j4">
        <type>transmission_interface/SimpleTransmission</type>
        <joint name="crisp_2_j4">
            <hardwareInterface>hardware_interface/EffortJointInterface</hardwareInterface>
        </joint>
        <actuator name="crisp_2_j4_motor">
            <hardwareInterface>hardware_interface/EffortJointInterface</hardwareInterface>
            <mechanicalReduction>1</mechanicalReduction>
        </actuator>
    </transmission>
    <transmission name="trans_crisp_2_j5">
        <type>transmission_interface/SimpleTransmission</type>
        <joint name="crisp_2_j5">
            <hardwareInterface>hardware_interface/EffortJointInterface</hardwareInterface>
        </joint>
        <actuator name="crisp_2_j5_motor">
            <hardwareInterface>hardware_interface/EffortJointInterface</hardwareInterface>
            <mechanicalReduction>1</mechanicalReduction>
        </actuator>
    </transmission>
    <transmission name="trans_crisp_2_j6">
        <type>transmission_interface/SimpleTransmission</type>
        <joint name="crisp_2_j6">
            <hardwareInterface>hardware_interface/EffortJointInterface</hardwareInterface>
        </joint>
        <actuator name="crisp_2_j6_motor">
            <hardwareInterface>hardware_interface/EffortJointInterface</hardwareInterface>
            <mechanicalReduction>1</mechanicalReduction>
        </actuator>
    </transmission>
    <transmission name="trans_crisp_3_j1">
        <type>transmission_interface/SimpleTransmission</type>
        <joint name="crisp_3_j1">
            <hardwareInterface>hardware_interface/EffortJointInterface</hardwareInterface>
        </joint>
        <actuator name="crisp_3_j1_motor">
            <hardwareInterface>hardware_interface/EffortJointInterface</hardwareInterface>
            <mechanicalReduction>1</mechanicalReduction>
        </actuator>
    </transmission>
    <transmission name="trans_crisp_3_j2">
        <type>transmission_interface/SimpleTransmission</type>
        <joint name="crisp_3_j2">
            <hardwareInterface>hardware_interface/EffortJointInterface</hardwareInterface>
        </joint>
        <actuator name="crisp_3_j2_motor">
            <hardwareInterface>hardware_interface/EffortJointInterface</hardwareInterface>
            <mechanicalReduction>1</mechanicalReduction>
        </actuator>
    </transmission>
    <transmission name="trans_crisp_3_j3">
        <type>transmission_interface/SimpleTransmission</type>
        <joint name="crisp_3_j3">
            <hardwareInterface>hardware_interface/EffortJointInterface</hardwareInterface>
        </joint>
        <actuator name="crisp_3_j3_motor">
            <hardwareInterface>hardware_interface/EffortJointInterface</hardwareInterface>
            <mechanicalReduction>1</mechanicalReduction>
        </actuator>
    </transmission>
    <transmission name="trans_crisp_3_j4">
        <type>transmission_interface/SimpleTransmission</type>
        <joint name="crisp_3_j4">
            <hardwareInterface>hardware_interface/EffortJointInterface</hardwareInterface>
        </joint>
        <actuator name="crisp_3_j4_motor">
            <hardwareInterface>hardware_interface/EffortJointInterface</hardwareInterface>
            <mechanicalReduction>1</mechanicalReduction>
        </actuator>
    </transmission>
    <transmission name="trans_crisp_3_j5">
        <type>transmission_interface/SimpleTransmission</type>
        <joint name="crisp_3_j5">
            <hardwareInterface>hardware_interface/EffortJointInterface</hardwareInterface>
        </joint>
        <actuator name="crisp_3_j5_motor">
            <hardwareInterface>hardware_interface/EffortJointInterface</hardwareInterface>
            <mechanicalReduction>1</mechanicalReduction>
        </actuator>
    </transmission>
    <transmission name="trans_crisp_3_j6">
        <type>transmission_interface/SimpleTransmission</type>
        <joint name="crisp_3_j6">
            <hardwareInterface>hardware_interface/EffortJointInterface</hardwareInterface>
        </joint>
        <actuator name="crisp_3_j6_motor">
            <hardwareInterface>hardware_interface/EffortJointInterface</hardwareInterface>
            <mechanicalReduction>1</mechanicalReduction>
        </actuator>
    </transmission>
    <transmission name="trans_crisp_4_j1">
        <type>transmission_interface/SimpleTransmission</type>
        <joint name="crisp_4_j1">
            <hardwareInterface>hardware_interface/EffortJointInterface</hardwareInterface>
        </joint>
        <actuator name="crisp_4_j1_motor">
            <hardwareInterface>hardware_interface/EffortJointInterface</hardwareInterface>
            <mechanicalReduction>1</mechanicalReduction>
        </actuator>
    </transmission>
    <transmission name="trans_crisp_4_j2">
        <type>transmission_interface/SimpleTransmission</type>
        <joint name="crisp_4_j2">
            <hardwareInterface>hardware_interface/EffortJointInterface</hardwareInterface>
        </joint>
        <actuator name="crisp_4_j2_motor">
            <hardwareInterface>hardware_interface/EffortJointInterface</hardwareInterface>
            <mechanicalReduction>1</mechanicalReduction>
        </actuator>
    </transmission>
    <transmission name="trans_crisp_4_j3">
        <type>transmission_interface/SimpleTransmission</type>
        <joint name="crisp_4_j3">
            <hardwareInterface>hardware_interface/EffortJointInterface</hardwareInterface>
        </joint>
        <actuator name="crisp_4_j3_motor">
            <hardwareInterface>hardware_interface/EffortJointInterface</hardwareInterface>
            <mechanicalReduction>1</mechanicalReduction>
        </actuator>
    </transmission>
    <transmission name="trans_crisp_4_j4">
        <type>transmission_interface/SimpleTransmission</type>
        <joint name="crisp_4_j4">
            <hardwareInterface>hardware_interface/EffortJointInterface</hardwareInterface>
        </joint>
        <actuator name="crisp_4_j4_motor">
            <hardwareInterface>hardware_interface/EffortJointInterface</hardwareInterface>
            <mechanicalReduction>1</mechanicalReduction>
        </actuator>
    </transmission>
    <transmission name="trans_crisp_4_j5">
        <type>transmission_interface/SimpleTransmission</type>
        <joint name="crisp_4_j5">
            <hardwareInterface>hardware_interface/EffortJointInterface</hardwareInterface>
        </joint>
        <actuator name="crisp_4_j5_motor">
            <hardwareInterface>hardware_interface/EffortJointInterface</hardwareInterface>
            <mechanicalReduction>1</mechanicalReduction>
        </actuator>
    </transmission>
    <transmission name="trans_crisp_4_j6">
        <type>transmission_interface/SimpleTransmission</type>
        <joint name="crisp_4_j6">
            <hardwareInterface>hardware_interface/EffortJointInterface</hardwareInterface>
        </joint>
        <actuator name="crisp_4_j6_motor">
            <hardwareInterface>hardware_interface/EffortJointInterface</hardwareInterface>
            <mechanicalReduction>1</mechanicalReduction>
        </actuator>
    </transmission>
    <gazebo>
        <plugin name="gazebo_ros_control">
            <robotNamespace>/</robotNamespace>
        </plugin>
    </gazebo>
</robot>

